<?xml version="1.0"?>
<robot name="bot" xmlns:xacro="http://www.ros.org/wiki/xacro">

<xacro:property name="wheelRadius" value="0.0732"/>
<xacro:property name="wheelLength" value="0.05575"/>
<xacro:property name="leftWheel" value="left_wheel"/>
<xacro:property name="rightWheel" value="right_wheel"/>

<xacro:macro name="wheel" params="side num reflect xv yv zv">
  <link name="${side}_${num}">
    <visual>
      <origin rpy="0 1.57079632679 0" xyz="${xv} ${yv} ${zv}"/>
      <geometry>
	      <mesh filename="package://bot_description/meshes/wheel.dae" />
      </geometry>
      <material name="Grey"/>
    </visual>
    <collision>
	    <origin rpy="3.14592 0 0" xyz="${xv} ${yv} ${zv}"/>
      <geometry>
         <cylinder radius="0.07" length="0.08"/>
      </geometry>
    </collision>
    <inertial>
      <mass value = "0.1" />
      <inertia ixx="0.00143" ixy="0.0" ixz="0.0" iyy="0.00143" iyz="0.0" izz="0.00125"/>
    </inertial>

</link>

  <link name="${side}_${num}_dummy">

    <inertial>
      <mass value = "0.1" />
      <inertia ixx="0.00143" ixy="0.0" ixz="0.0" iyy="0.00143" iyz="0.0" izz="0.00125"/>
    </inertial>
  </link>

 <joint name="${side}_${num}_rev" type="revolute">
    <axis xyz="0 0 1" />
    <limit lower="-0.523599" upper="0.523599" effort="10000.0" velocity="100"/>
    <parent link="base_link"/>
    <child link="${side}_${num}_dummy"/>
    <origin rpy="0 0 0" xyz="${0.3 - (0.2 * num)} ${0.2 * reflect}  -0.10"/>
  </joint>

  <transmission name="${side}_${num}_trans2">
    <type>transmission_interface/SimpleTransmission</type>
    <actuator name="${side}_${num}_actuator2">
      <mechanicalReduction>1</mechanicalReduction>
      <hardwareInterface>hardware_interface/VelocityJointInterface </hardwareInterface>
    </actuator>
    <joint name="${side}_${num}_rev">
      <hardwareInterface>hardware_interface/VelocityJointInterface </hardwareInterface>
    </joint>
  </transmission>

  <joint name="${side}_${num}_joint" type="continuous">
    <axis xyz="0 0 1" />
    <limit effort="10000.0" velocity="100"/>
    <parent link="${side}_${num}_dummy"/>
    <child link="${side}_${num}"/>
    <origin rpy="0 ${3.14592/2} 1.57079632679" xyz="0 0 0"/>
  </joint>


  <gazebo reference="${side}_${num}_link">
    <material>Gazebo/Grey</material>
  </gazebo>



 <transmission name="${side}_${num}_trans">
    <type>transmission_interface/SimpleTransmission</type>
    <actuator name="${side}_${num}_actuator">
      <mechanicalReduction>1</mechanicalReduction>
      <hardwareInterface>hardware_interface/VelocityJointInterface</hardwareInterface>
    </actuator>
    <joint name="${side}_${num}_joint">
      <hardwareInterface>hardware_interface/VelocityJointInterface</hardwareInterface>
    </joint>
  </transmission>
</xacro:macro>

<!-- ============================= SENSORS ========================================= -->
<link name="hokuyo_link">
        <visual>
			<origin rpy="0 0 0" xyz="0 0 0"/>
            <geometry>
                <box size="0.1 0.1 0.1"/>
            </geometry>
			<material name="blue"/>
        </visual>
    </link>

	<joint name="hokuyo_joint" type="fixed">
		<parent link="base_link"/>
		<child link="hokuyo_link"/>
		<origin xyz="0.0 0.0 0.30" rpy="0 0 0" />
	</joint>

	<gazebo reference="hokuyo_link">
    <material>Gazebo/White</material>
	    <sensor name="head_hokuyo_sensor" type="ray">
	      <pose>0.05 0 0 0 0 0</pose>
	      <visualize>true</visualize>
	      <update_rate>40</update_rate>
	      <ray>
	        <scan>
	          <horizontal>
	            <samples>720</samples>
	            <resolution>1</resolution>
	            <min_angle>-1.570796</min_angle>
	            <max_angle>1.570796</max_angle>
	          </horizontal>
	        </scan>
	        <range>
	          <min>0.10</min>
	          <max>10.0</max>
	          <resolution>0.001</resolution>
	        </range>
	      </ray>
	      <plugin filename="libgazebo_ros_laser.so" name="gazebo_ros_head_hokuyo_controller">
	        <topicName>/scan</topicName>
	        <frameName>hokuyo_link</frameName>
	      </plugin>
	    </sensor>
  	</gazebo>

  <material name="blue">
    <color rgba="0 0 0.8 1"/>
</material>

  <material name="white">
    <color rgba="1 1 1 1"/>
  </material>

 <material name="black">
    <color rgba="0 0 0 1"/>
  </material>


  <link name="base_link">
    <visual>
      <geometry> 
        <mesh filename="package://bot_description/meshes/carfullblended.dae"/>
      </geometry>
      <origin rpy="0 0 1.5712645" xyz="-0.01 -0.007 -0.08"/>
      <material name="white"/>
      
    </visual>
    <collision>
      <geometry>
        <mesh filename="package://bot_description/meshes/carfullblended.dae"/>
      </geometry>
      <origin rpy="0 0 1.5712645" xyz="-0.01 -0.007 -0.08"/>
    </collision>
    
  </link>

  <link name="dummy_link">
    <inertial>
      <mass value = "1" />
      <inertia ixx="0.05666" ixy="0.0" ixz="0.0" iyy="0.00666" iyz="0.0" izz="0.05666"/>
    </inertial>
  </link>

  <joint name="dummy_joint" type="fixed">
    <parent link="base_link"/>
    <child link="dummy_link"/>
    <origin rpy="0 0 0" xyz="0 0 0"/>
  </joint>
  
<xacro:wheel side="left_wheel" num="0" reflect="1" xv="0" yv="0" zv="0.02"/>
<xacro:wheel side="left_wheel" num="1" reflect="1" xv="0" yv="0" zv="0.02"/>
<xacro:wheel side="left_wheel" num="2" reflect="1" xv="0" yv="0" zv="0.02"/>
<xacro:wheel side="left_wheel" num="3" reflect="1" xv="0" yv="0" zv="0.02"/>
<xacro:wheel side="right_wheel" num="0" reflect="-1" xv="0" yv="0" zv="-0.02"/>
<xacro:wheel side="right_wheel" num="1" reflect="-1" xv="0" yv="0" zv="-0.02"/>
<xacro:wheel side="right_wheel" num="2" reflect="-1" xv="0" yv="0" zv="-0.02"/>
<xacro:wheel side="right_wheel" num="3" reflect="-1" xv="0" yv="0" zv="-0.02"/>

  <gazebo>
    <plugin name="gazebo_ros_control" filename="libgazebo_ros_control.so">
    <robotNamespace>/bot</robotNamespace>
        <robotSimType>gazebo_ros_control/DefaultRobotHWSim</robotSimType>
  </plugin> 

  <plugin name="p3d_base_controller" filename="libgazebo_ros_p3d.so">
    <alwaysOn>true</alwaysOn>
    <updateRate>50.0</updateRate>
    <bodyName>base_link</bodyName>
    <topicName>/odom</topicName>
    <gaussianNoise>0.01</gaussianNoise>
    <frameName>world</frameName>
    <xyzOffsets>0 0 0</xyzOffsets>
    <rpyOffsets>0 0 0</rpyOffsets>
  </plugin>

  </gazebo>

</robot>
