<?xml version="1.0"?>
<robot name="bot" xmlns:xacro="http://www.ros.org/wiki/xacro">

<xacro:property name="wheelRadius" value="0.0932"/>
<xacro:property name="wheelLength" value="0.07575"/>
<xacro:property name="leftWheel" value="left_wheel"/>
<xacro:property name="rightWheel" value="right_wheel"/>

<xacro:macro name="wheel" params="side num reflect">
  <link name="${side}_${num}">
    <visual>
      <geometry>
        <cylinder length="${wheelLength}" radius="${wheelRadius}"/>
        <origin rpy="0 ${3.14592/2} 0" xyz="${0.2 * reflect} ${0.3 - (0.2 * num)} -0.12"/>
      </geometry>
      <material name="Black"/>
    </visual>
    <collision>
      <geometry>
         <cylinder length="${wheelLength}" radius="${wheelRadius}"/>
         <origin rpy="0 ${3.14592/2} 0" xyz="${0.2 * reflect} ${0.3 - (0.2 * num)} -0.12"/>
      </geometry>
    </collision>
    <inertial>
      <mass value = "1" />
      <inertia ixx="0.00143" ixy="0.0" ixz="0.0" iyy="0.00143" iyz="0.0" izz="0.00125"/>
    </inertial>

</link>

  <joint name="${side}_${num}_joint" type="continuous">
    <axis xyz="0 0 1" />
    <limit effort="10000.0" velocity="3"/>
    <parent link="base_link"/>
    <child link="${side}_${num}"/>
    <origin rpy="0 ${3.14592/2} 0" xyz="${0.2 * reflect} ${0.3 - (0.2 * num)} -0.12"/>
  </joint>

  <gazebo reference="${side}_${num}">
    <mu1 value="100.0"/>
    <mu2 value="50.0"/>
    <kp value="10000000.0" />
    <kd value="1.0" />
    <material>Gazebo/Red</material>
  </gazebo>
</xacro:macro>

<xacro:macro name="transmissions" params="num side">

    <transmission name="${side}_${num}_trans">
      <type>transmission_interface/SimpleTransmission</type>
      <actuator name="${side}_${num}_motor">
        <mechanicalReduction>1</mechanicalReduction>
        <hardwareInterface>hardware_interface/VelocityJointInterface</hardwareInterface>
      </actuator>
      <joint name="${side}_${num}_joint">
        <hardwareInterface>hardware_interface/VelocityJointInterface</hardwareInterface>
      </joint>
    </transmission>
</xacro:macro>
<!-- ============================= SENSORS ========================================= -->
<link name="hokuyo_link">
        <visual>
			<origin rpy="0 0 0" xyz="0 0 0"/>
            <geometry>
                <box size="0.1 0.1 0.1"/>
            </geometry>
			<material name="blue"/>
        </visual>
    </link>

	<joint name="hokuyo_joint" type="fixed">
		<parent link="base_link"/>
		<child link="hokuyo_link"/>
		<origin xyz="0.0 -0.13 0.25" rpy="0 0 -1.572" />
	</joint>

	<gazebo reference="hokuyo_link">
    <material>Gazebo/White</material>
	    <sensor name="head_hokuyo_sensor" type="ray">
	      <pose>0.05 0 0 0 0 0</pose>
	      <visualize>true</visualize>
	      <update_rate>40</update_rate>
	      <ray>
	        <scan>
	          <horizontal>
	            <samples>720</samples>
	            <resolution>1</resolution>
	            <min_angle>-1.570796</min_angle>
	            <max_angle>1.570796</max_angle>
	          </horizontal>
	        </scan>
	        <range>
	          <min>0.10</min>
	          <max>10.0</max>
	          <resolution>0.001</resolution>
	        </range>
	      </ray>
	      <plugin filename="libgazebo_ros_laser.so" name="gazebo_ros_head_hokuyo_controller">
	        <topicName>/scan</topicName>
	        <frameName>hokuyo_link</frameName>
	      </plugin>
	    </sensor>
  	</gazebo>

  <material name="blue">
    <color rgba="0 0 0.8 1"/>
</material>

  <material name="white">
    <color rgba="1 1 1 1"/>
  </material>

 <material name="black">
    <color rgba="0 0 0 1"/>
  </material>


  <link name="base_link">
    <visual>
      <geometry>
        <mesh filename="package://bot_description/meshes/carfullblended.dae"/>
      </geometry>
      <origin rpy="0 0 0" xyz="0.044112 -0.311197 -0.038199"/>
      <material name="grey"/>
    </visual>
    <collision>
      <geometry>
        <mesh filename="package://bot_description/meshes/carfullblended.dae"/>
      </geometry>
      <origin rpy="0 0 0" xyz="0 0 0"/>
    </collision>
    
  </link>

  <link name="dummy_link">
    <inertial>
      <mass value = "10" />
      <inertia ixx="0.05666" ixy="0.0" ixz="0.0" iyy="0.00666" iyz="0.0" izz="0.05666"/>
    </inertial>
  </link>

  <joint name="dummy_joint" type="fixed">
    <parent link="base_link"/>
    <child link="dummy_link"/>
    <origin rpy="0 0 0" xyz="0 0 0"/>
  </joint>
  
<xacro:wheel side="left_wheel" num="0" reflect="-1"/>
<xacro:wheel side="left_wheel" num="1" reflect="-1"/>
<xacro:wheel side="left_wheel" num="2" reflect="-1"/>
<xacro:wheel side="left_wheel" num="3" reflect="-1"/>
<xacro:wheel side="right_wheel" num="0" reflect="1"/>
<xacro:wheel side="right_wheel" num="1" reflect="1"/>
<xacro:wheel side="right_wheel" num="2" reflect="1"/>
<xacro:wheel side="right_wheel" num="3" reflect="1"/>

  <gazebo>
  <plugin name="gazebo_ros_control" filename="libgazebo_ros_control.so">
    <robotNamespace>/bot</robotNamespace>
  </plugin> 

  <plugin name="p3d_base_controller" filename="libgazebo_ros_p3d.so">
    <alwaysOn>true</alwaysOn>
    <updateRate>50.0</updateRate>
    <bodyName>base_link</bodyName>
    <topicName>/odom</topicName>
    <gaussianNoise>0.01</gaussianNoise>
    <frameName>world</frameName>
    <xyzOffsets>0 0 0</xyzOffsets>
    <rpyOffsets>0 0 0</rpyOffsets>
  </plugin>

  </gazebo>

<xacro:transmissions side="left_wheel" num="0"/>
<xacro:transmissions side="left_wheel" num="1"/>
<xacro:transmissions side="left_wheel" num="2"/>
<xacro:transmissions side="left_wheel" num="3"/>
<xacro:transmissions side="right_wheel" num="0"/>
<xacro:transmissions side="right_wheel" num="1"/>
<xacro:transmissions side="right_wheel" num="2"/>
<xacro:transmissions side="right_wheel" num="3"/>

</robot>
